<mujoco model="2d_hopper">
  <option gravity="0 0 -9.81"/>
  <default>
    <geom friction="1 0.005 0.0001" condim="3"/>
    <motor ctrllimited="true" ctrlrange="-200 200"/>
  </default>

  <worldbody>
    <geom type="plane" size="5 5 0.1" rgba="0.2 0.2 0.2 1"/>
    <geom type="box" size="5 0.1 0.01" pos="0 0 0" rgba="0.3 0.3 0.3 1"/>

    <!-- Base body with constrained 2D joints -->
    <body name="hopper_base" pos="0 0 0.1">
      <joint name="slide_x" type="slide" axis="1 0 0"/>
      <joint name="slide_z" type="slide" axis="0 0 1"/>
      <joint name="rot_y" type="hinge" axis="0 1 0"/>
      <geom type="capsule" fromto="0 0 0 0 0 0.3" size="0.05"/>

      <!-- Upper body -->
      <body name="torso" pos="0 0 0.3">
        <!-- <joint name="hip" type="hinge" axis="0 1 0" limited="true" range="-90 90"/> -->
        <joint name="hip" type="hinge" axis="0 1 0" limited="false"/>
        <geom type="capsule" fromto="0 0 0 0 0 0.3" size="0.05"/>
      </body>
    </body>
  </worldbody>

  <actuator>
    <motor joint="hip" gear="1"/>
  </actuator>
</mujoco>

